const User = require('../models/userModel');
const catchAsync = require('../utilities/catchAsync');

exports.getAllUsers = async (req, res) => {
  try {
    const users = await User.find();

    res.status(200).json({
      status: 'success',
      data: {
        users,
      },
    });
  } catch (err) {
    res.status(404).json({
      status: 'fail',
      message: err,
    });
  }
};

exports.getUser = async (req, res) => {
  try {
    const user = await User.findById(req.params.id);
    res.status(200).json({
      status: 'success',
      data: {
        user,
      },
    });
  } catch (err) {
    res.status(404).json({
      status: 'fail',
      message: err,
    });
  }
};

exports.createUser = catchAsync(async (req, res) => {

  const newUser = await User.create(req.body);

  res.status(201).json({
    status: 'success',
    data: {
      newUser,
    },
  });

});

exports.updateUser = async (req, res) => {
  try {
    const user = await User.findByIdAndUpdate(req.params.id, req.body, {
      new: true, //send the new obj
      runValidators: true, // validates if new data types are consistent with model's data types
    });
    res.status(200).json({
      status: 'success',
      data: {
        user,
      },
    });
  } catch (err) {
    res.status(404).json({
      status: 'fail',
      message: err,
    });
  }
};

exports.deleteUser = async (req, res) => {
  try {
    await User.findByIdAndDelete(req.params.id);

    res.status(204).json({
      status: 'success',
      data: null,
    });
  } catch (err) {
    res.status(404).json({
      status: 'fail',
      message: err,
    });
  }
};
